<?xml version="1.0" ?>
<robot name="wmr" xmlns:xacro="http://www.ros.org/wiki/xacro">

<xacro:include filename="$(find wmr_description)/urdf/materials.xacro" />
<xacro:include filename="$(find wmr_description)/urdf/wmr.trans" />
<xacro:include filename="$(find wmr_description)/gazebo/wmr_detailed_material.gazebo" />
<xacro:include filename="$(find wmr_description)/gazebo/wmr_detailed_physics.gazebo" />
<xacro:include filename="$(find wmr_description)/gazebo/wmr_detailed_plugins.gazebo" />

<link name="base_link">
  <inertial>
    <origin xyz="0.004386500845627422 -3.4220383966176395e-17 0.057193250424025434" rpy="0 0 0"/>
    <mass value="5.0518647915777475"/>
    <inertia ixx="0.017915" iyy="0.038599" izz="0.051557" ixy="-0.0" iyz="-0.0" ixz="-0.001004"/>
  </inertial>
  <visual>
    <origin xyz="0 0 0" rpy="0 0 0"/>
    <geometry>
      <mesh filename="package://wmr_description/meshes/base_link.stl" scale="0.001 0.001 0.001"/>
    </geometry>
    <material name="silver"/>
  </visual>
  <collision>
    <origin xyz="0 0 0" rpy="0 0 0"/>
    <geometry>
      <mesh filename="package://wmr_description/meshes/base_link.stl" scale="0.001 0.001 0.001"/>
    </geometry>
  </collision>
</link>

<link name="Lidar_1">
  <inertial>
    <origin xyz="-1.3877787807814457e-17 -1.447505775030507e-17 0.009999999999999995" rpy="0 0 0"/>
    <mass value="0.42411500823462206"/>
    <inertia ixx="0.000279" iyy="0.000279" izz="0.00053" ixy="-0.0" iyz="-0.0" ixz="0.0"/>
  </inertial>
  <visual>
    <origin xyz="-0.095 -0.0 -0.115" rpy="0 0 0"/>
    <geometry>
      <mesh filename="package://wmr_description/meshes/Lidar_1.stl" scale="0.001 0.001 0.001"/>
    </geometry>
    <material name="silver"/>
  </visual>
  <collision>
    <origin xyz="-0.095 -0.0 -0.115" rpy="0 0 0"/>
    <geometry>
      <mesh filename="package://wmr_description/meshes/Lidar_1.stl" scale="0.001 0.001 0.001"/>
    </geometry>
  </collision>
</link>

<link name="caster_left_back_1">
  <inertial>
    <origin xyz="1.5265566588595902e-16 -8.326672684688674e-17 -0.007916666666666667" rpy="0 0 0"/>
    <mass value="0.028627763055837"/>
    <inertia ixx="2e-06" iyy="2e-06" izz="3e-06" ixy="-0.0" iyz="0.0" ixz="-0.0"/>
  </inertial>
  <visual>
    <origin xyz="0.1 -0.05 -0.02" rpy="0 0 0"/>
    <geometry>
      <mesh filename="package://wmr_description/meshes/caster_left_back_1.stl" scale="0.001 0.001 0.001"/>
    </geometry>
    <material name="silver"/>
  </visual>
  <collision>
    <origin xyz="0.1 -0.05 -0.02" rpy="0 0 0"/>
    <geometry>
      <mesh filename="package://wmr_description/meshes/caster_left_back_1.stl" scale="0.001 0.001 0.001"/>
    </geometry>
  </collision>
</link>

<link name="caster_right_back_1">
  <inertial>
    <origin xyz="4.163336342344337e-17 -4.163336342344337e-17 -0.007916666666666667" rpy="0 0 0"/>
    <mass value="0.028627763055836974"/>
    <inertia ixx="2e-06" iyy="2e-06" izz="3e-06" ixy="0.0" iyz="0.0" ixz="0.0"/>
  </inertial>
  <visual>
    <origin xyz="0.1 0.05 -0.02" rpy="0 0 0"/>
    <geometry>
      <mesh filename="package://wmr_description/meshes/caster_right_back_1.stl" scale="0.001 0.001 0.001"/>
    </geometry>
    <material name="silver"/>
  </visual>
  <collision>
    <origin xyz="0.1 0.05 -0.02" rpy="0 0 0"/>
    <geometry>
      <mesh filename="package://wmr_description/meshes/caster_right_back_1.stl" scale="0.001 0.001 0.001"/>
    </geometry>
  </collision>
</link>

<link name="caster_right_front_1">
  <inertial>
    <origin xyz="-9.71445146547012e-17 1.5959455978986625e-16 -0.007916666666666667" rpy="0 0 0"/>
    <mass value="0.028627763055837"/>
    <inertia ixx="2e-06" iyy="2e-06" izz="3e-06" ixy="-0.0" iyz="-0.0" ixz="-0.0"/>
  </inertial>
  <visual>
    <origin xyz="-0.1 0.05 -0.02" rpy="0 0 0"/>
    <geometry>
      <mesh filename="package://wmr_description/meshes/caster_right_front_1.stl" scale="0.001 0.001 0.001"/>
    </geometry>
    <material name="silver"/>
  </visual>
  <collision>
    <origin xyz="-0.1 0.05 -0.02" rpy="0 0 0"/>
    <geometry>
      <mesh filename="package://wmr_description/meshes/caster_right_front_1.stl" scale="0.001 0.001 0.001"/>
    </geometry>
  </collision>
</link>

<link name="caster_left_front_1">
  <inertial>
    <origin xyz="1.3877787807814457e-16 8.326672684688674e-17 -0.007916666666666667" rpy="0 0 0"/>
    <mass value="0.028627763055836974"/>
    <inertia ixx="2e-06" iyy="2e-06" izz="3e-06" ixy="0.0" iyz="0.0" ixz="0.0"/>
  </inertial>
  <visual>
    <origin xyz="-0.1 -0.05 -0.02" rpy="0 0 0"/>
    <geometry>
      <mesh filename="package://wmr_description/meshes/caster_left_front_1.stl" scale="0.001 0.001 0.001"/>
    </geometry>
    <material name="silver"/>
  </visual>
  <collision>
    <origin xyz="-0.1 -0.05 -0.02" rpy="0 0 0"/>
    <geometry>
      <mesh filename="package://wmr_description/meshes/caster_left_front_1.stl" scale="0.001 0.001 0.001"/>
    </geometry>
  </collision>
</link>

<link name="left_wheel_1">
  <inertial>
    <origin xyz="2.39278252948906e-06 0.004895652123634409 -7.168491681554257e-05" rpy="0 0 0"/>
    <mass value="0.14679988597311447"/>
    <inertia ixx="0.000115" iyy="0.000222" izz="0.000115" ixy="-0.0" iyz="0.0" ixz="0.0"/>
  </inertial>
  <visual>
    <origin xyz="-0.0 -0.11 -0.055" rpy="0 0 0"/>
    <geometry>
      <mesh filename="package://wmr_description/meshes/left_wheel_1.stl" scale="0.001 0.001 0.001"/>
    </geometry>
    <material name="silver"/>
  </visual>
  <collision>
    <origin xyz="-0.0 -0.11 -0.055" rpy="0 0 0"/>
    <geometry>
      <mesh filename="package://wmr_description/meshes/left_wheel_1.stl" scale="0.001 0.001 0.001"/>
    </geometry>
  </collision>
</link>

<link name="right_wheel_1">
  <inertial>
    <origin xyz="-2.392782529448616e-06 -0.004895652123634436 7.168655594325807e-05" rpy="0 0 0"/>
    <mass value="0.14679988597311452"/>
    <inertia ixx="0.000115" iyy="0.000222" izz="0.000115" ixy="-0.0" iyz="0.0" ixz="0.0"/>
  </inertial>
  <visual>
    <origin xyz="-0.0 0.11 -0.055" rpy="0 0 0"/>
    <geometry>
      <mesh filename="package://wmr_description/meshes/right_wheel_1.stl" scale="0.001 0.001 0.001"/>
    </geometry>
    <material name="silver"/>
  </visual>
  <collision>
    <origin xyz="-0.0 0.11 -0.055" rpy="0 0 0"/>
    <geometry>
      <mesh filename="package://wmr_description/meshes/right_wheel_1.stl" scale="0.001 0.001 0.001"/>
    </geometry>
  </collision>
</link>

<joint name="lidar_rigid" type="fixed">
  <origin xyz="0.095 0.0 0.115" rpy="0 0 0"/>
  <parent link="base_link"/>
  <child link="Lidar_1"/>
</joint>

<joint name="caster_left_back_rigid" type="fixed">
  <origin xyz="-0.1 0.05 0.02" rpy="0 0 0"/>
  <parent link="base_link"/>
  <child link="caster_left_back_1"/>
</joint>

<joint name="caster_right_back_rigid" type="fixed">
  <origin xyz="-0.1 -0.05 0.02" rpy="0 0 0"/>
  <parent link="base_link"/>
  <child link="caster_right_back_1"/>
</joint>

<joint name="caster_right_front_rigid" type="fixed">
  <origin xyz="0.1 -0.05 0.02" rpy="0 0 0"/>
  <parent link="base_link"/>
  <child link="caster_right_front_1"/>
</joint>

<joint name="caster_left_front_rigid" type="fixed">
  <origin xyz="0.1 0.05 0.02" rpy="0 0 0"/>
  <parent link="base_link"/>
  <child link="caster_left_front_1"/>
</joint>

<joint name="left_revolute" type="continuous">
  <origin xyz="0.0 0.11 0.055" rpy="0 0 0"/>
  <parent link="base_link"/>
  <child link="left_wheel_1"/>
  <axis xyz="0.0 1.0 0.0"/>
</joint>

<joint name="right_revolute" type="continuous">
  <origin xyz="0.0 -0.11 0.055" rpy="0 0 0"/>
  <parent link="base_link"/>
  <child link="right_wheel_1"/>
  <axis xyz="0.0 1.0 0.0"/>
</joint>

</robot>
